# Duplicate Response Fix - PATH 3

## Issue

Bot was sending responses in **two places**:
1. In the thread (correct)
2. In the main channel (incorrect - fallback handler)

Example Discord links showing duplicate:
- Thread response: `/channels/.../1431456548151889980/1431456559224983554`
- Channel response: `/channels/.../1377322106781569046/1431456523686776954`

## Root Cause

In `command_handler.py`, after PATH 3 successfully created a thread and processed the command, there was **no return statement**.

```python
if thread:
    logger.info(f"‚úÖ PATH 3: Created bot thread '{thread.name}'")
    # ... process in thread ...
    await _process_bot_command_in_thread(...)
    # ‚ùå NO RETURN HERE - execution continues!
else:
    await _handle_bot_command_fallback(...)  # This was being called

except Exception as e:
    await _handle_bot_command_fallback(...)  # Or this if exception
```

### What Happened

1. Bot creates thread successfully (PATH 3)
2. Sends "Processing your request..." in thread ‚úÖ
3. Processes command in thread ‚úÖ
4. **No return** - execution continues
5. If `_process_bot_command_in_thread` raises exception:
   - Exception caught by outer try-except
   - Fallback handler called ‚ùå
   - Sends response in main channel ‚ùå
6. Result: Two responses (thread + channel)

## Solution

Added explicit `return` statement after PATH 3 processing:

```python
if thread:
    logger.info(f"‚úÖ PATH 3: Created bot thread '{thread.name}'")
    thread_sender = MessageResponseSender(thread)
    processing_msg = await thread_sender.send(
        "Processing your request, please wait..."
    )
    await _process_bot_command_in_thread(
        thread_sender, processing_msg, message, query, bot_client, thread.id
    )
    logger.debug(f"PATH 3 completed successfully, returning from handle_bot_command")
    return  # ‚úÖ ADDED - prevents fallback from being called
else:
    await _handle_bot_command_fallback(...)
```

## Changes Made

### File: `command_handler.py`

**Line 329-330**: Added return statement after PATH 3 processing

```python
# After successful PATH 3 processing
logger.debug(f"PATH 3 completed successfully, returning from handle_bot_command")
return
```

## Expected Behavior After Fix

### Scenario: Normal Mention (PATH 3)

```
User: "@bot analyze this data"

Flow:
1. Bot creates thread ‚úÖ
2. Sends processing message in thread ‚úÖ
3. Processes command in thread ‚úÖ
4. Returns immediately ‚úÖ
5. No fallback called ‚úÖ

Result: ONE response in thread only
```

### Logs After Fix

**Success (no fallback)**:
```
INFO - Creating bot thread (message has NO attachments)
INFO - Successfully created thread 'Bot Response - Dr. vova'
INFO - ‚úÖ PATH 3: Created bot thread 'Bot Response - Dr. vova'
DEBUG - PATH 3 completed successfully, returning from handle_bot_command
INFO - Command executed successfully: mention - Response length: XXX
```

**Should NOT see**:
```
‚ùå INFO - Calling fallback handler due to exception in main handler
‚ùå INFO - üîÑ FALLBACK: Responding in channel XXX
```

## Why This Happened

Looking at PATH 1 and PATH 2, they both have `return` statements:

**PATH 1** (line 264):
```python
await _process_bot_command_in_thread(...)
return  # ‚úÖ Has return
```

**PATH 2** (line 298):
```python
await _process_bot_command_in_thread(...)
return  # ‚úÖ Has return
```

**PATH 3** (line 328 - BEFORE FIX):
```python
await _process_bot_command_in_thread(...)
# ‚ùå NO RETURN - BUG!
```

PATH 3 was missing its return statement, causing execution to continue and potentially trigger the exception handler.

## Exception Handling

Even with the return statement, if `_process_bot_command_in_thread` raises an exception:
- Exception is caught by outer try-except
- Fallback handler is called
- Response sent in channel

**However**, `_process_bot_command_in_thread` has its own try-except that handles errors internally, so exceptions should be rare.

## Testing

Test all three paths:

### Test 1: PATH 1 (Already in Thread)
```
1. Send message with attachment
2. Discord creates thread
3. In that thread, mention bot
Expected: Response in same thread only
```

### Test 2: PATH 2 (Attachment - Wait for Discord Thread)
```
User: "@bot what's in this?" + [image.png]
Expected: Response in Discord's auto-created thread only
```

### Test 3: PATH 3 (Bot Creates Thread)
```
User: "@bot hello"
Expected: Response in bot-created thread only
```

## Verification

After deploying, monitor logs for:

**‚úÖ Good**:
```
INFO - ‚úÖ PATH X: ...
DEBUG - PATH X completed successfully, returning
INFO - Command executed successfully
```

**‚ùå Bad** (indicates fallback being triggered):
```
INFO - ‚úÖ PATH 3: Created bot thread
ERROR - Error in thread-based bot command handling
INFO - Calling fallback handler due to exception
INFO - üîÑ FALLBACK: Responding in channel
```

## Related Fixes

This completes the thread handling fixes:
1. ‚úÖ Message deduplication (bot.py)
2. ‚úÖ Thread reuse when already exists (command_abstraction.py)
3. ‚úÖ Auto-thread detection for attachments (command_handler.py - PATH 2)
4. ‚úÖ PATH 3 return statement (this fix)

Combined result: **Exactly one response per command, in the correct location.**

## Impact

- **Before**: Some commands resulted in duplicate responses (thread + channel)
- **After**: All commands result in single response in correct location

## Rollback

If this causes issues:
```bash
git diff command_handler.py | grep -A 2 "PATH 3 completed"
git checkout HEAD~1 command_handler.py
```

## Date

2025-10-24
